EEEEEEEEEEEEEEEEEEEEEEEEEEEEEEEE..EEEE..EEE.......................................................................................E.EEE........................
======================================================================
ERROR: test_eh_senha_valida_025 (__main__.TestDepuracao5)
Exemplo enunciado ('aabcd', {'vals': (1,3), 'char':'a'})
----------------------------------------------------------------------
Traceback (most recent call last):
  File "proj_tester.py", line 748, in test_eh_senha_valida_025
    self.assertTrue(target.eh_senha_valida("aabcde", {"vals": (1, 3), "char": "a"}))
AttributeError: module 'target' has no attribute 'eh_senha_valida'

======================================================================
ERROR: test_eh_senha_valida_026 (__main__.TestDepuracao5)
Exemplo enunciado ('cdefgh', {'vals': (1,3), 'char':'b'})
----------------------------------------------------------------------
Traceback (most recent call last):
  File "proj_tester.py", line 755, in test_eh_senha_valida_026
    target.eh_senha_valida("cdefgh", {"vals": (1, 3), "char": "b"})
AttributeError: module 'target' has no attribute 'eh_senha_valida'

======================================================================
ERROR: test_eh_senha_valida_119 (__main__.TestDepuracao5)
----------------------------------------------------------------------
Traceback (most recent call last):
  File "proj_tester.py", line 760, in test_eh_senha_valida_119
    target.eh_senha_valida("aaaaa", {"vals": (1, 5), "char": "a"})
AttributeError: module 'target' has no attribute 'eh_senha_valida'

======================================================================
ERROR: test_eh_senha_valida_120 (__main__.TestDepuracao5)
----------------------------------------------------------------------
Traceback (most recent call last):
  File "proj_tester.py", line 765, in test_eh_senha_valida_120
    target.eh_senha_valida("aaaaaa", {"vals": (1, 5), "char": "a"})
AttributeError: module 'target' has no attribute 'eh_senha_valida'

======================================================================
ERROR: test_eh_senha_valida_121 (__main__.TestDepuracao5)
----------------------------------------------------------------------
Traceback (most recent call last):
  File "proj_tester.py", line 770, in test_eh_senha_valida_121
    target.eh_senha_valida("aaaaa", {"vals": (2, 5), "char": "d"})
AttributeError: module 'target' has no attribute 'eh_senha_valida'

======================================================================
ERROR: test_eh_senha_valida_122 (__main__.TestDepuracao5)
----------------------------------------------------------------------
Traceback (most recent call last):
  File "proj_tester.py", line 775, in test_eh_senha_valida_122
    target.eh_senha_valida("ddddei", {"vals": (2, 5), "char": "d"})
AttributeError: module 'target' has no attribute 'eh_senha_valida'

======================================================================
ERROR: test_eh_senha_valida_123 (__main__.TestDepuracao5)
----------------------------------------------------------------------
Traceback (most recent call last):
  File "proj_tester.py", line 780, in test_eh_senha_valida_123
    target.eh_senha_valida("addddei", {"vals": (2, 5), "char": "d"})
AttributeError: module 'target' has no attribute 'eh_senha_valida'

======================================================================
ERROR: test_eh_senha_valida_124 (__main__.TestDepuracao5)
----------------------------------------------------------------------
Traceback (most recent call last):
  File "proj_tester.py", line 785, in test_eh_senha_valida_124
    target.eh_senha_valida("adedidodei", {"vals": (2, 5), "char": "d"})
AttributeError: module 'target' has no attribute 'eh_senha_valida'

======================================================================
ERROR: test_eh_senha_valida_125 (__main__.TestDepuracao5)
----------------------------------------------------------------------
Traceback (most recent call last):
  File "proj_tester.py", line 790, in test_eh_senha_valida_125
    target.eh_senha_valida("ajejidojeii", {"vals": (3, 3), "char": "j"})
AttributeError: module 'target' has no attribute 'eh_senha_valida'

======================================================================
ERROR: test_eh_senha_valida_126 (__main__.TestDepuracao5)
----------------------------------------------------------------------
Traceback (most recent call last):
  File "proj_tester.py", line 795, in test_eh_senha_valida_126
    target.eh_senha_valida("aXaxaaa", {"vals": (1, 3), "char": "X"})
AttributeError: module 'target' has no attribute 'eh_senha_valida'

======================================================================
ERROR: test_eh_senha_valida_127 (__main__.TestDepuracao5)
----------------------------------------------------------------------
Traceback (most recent call last):
  File "proj_tester.py", line 800, in test_eh_senha_valida_127
    target.eh_senha_valida("..adedidodei", {"vals": (2, 5), "char": "d"})
AttributeError: module 'target' has no attribute 'eh_senha_valida'

======================================================================
ERROR: test_eh_senha_valida_128 (__main__.TestDepuracao5)
----------------------------------------------------------------------
Traceback (most recent call last):
  File "proj_tester.py", line 805, in test_eh_senha_valida_128
    target.eh_senha_valida("fundamentosdaprogramacao21-22", {"vals": (2, 5), "char": "n"})
AttributeError: module 'target' has no attribute 'eh_senha_valida'

======================================================================
ERROR: test_eh_utilizador_023 (__main__.TestDepuracao5)
Exemplo enunciado {'name':'john.doe','pass':'aabcde','rule':{'vals':(1,3),'char':'a'}}
----------------------------------------------------------------------
Traceback (most recent call last):
  File "proj_tester.py", line 597, in test_eh_utilizador_023
    target.eh_utilizador(
AttributeError: module 'target' has no attribute 'eh_utilizador'

======================================================================
ERROR: test_eh_utilizador_024 (__main__.TestDepuracao5)
Exemplo enunciado {'name':'john.doe','pass':'aabcde','rule':{'vals':1,'char':'a'}}
----------------------------------------------------------------------
Traceback (most recent call last):
  File "proj_tester.py", line 611, in test_eh_utilizador_024
    target.eh_utilizador(
AttributeError: module 'target' has no attribute 'eh_utilizador'

======================================================================
ERROR: test_eh_utilizador_107 (__main__.TestDepuracao5)
----------------------------------------------------------------------
Traceback (most recent call last):
  File "proj_tester.py", line 617, in test_eh_utilizador_107
    self.assertFalse(target.eh_utilizador(56.7))
AttributeError: module 'target' has no attribute 'eh_utilizador'

======================================================================
ERROR: test_eh_utilizador_108 (__main__.TestDepuracao5)
----------------------------------------------------------------------
Traceback (most recent call last):
  File "proj_tester.py", line 620, in test_eh_utilizador_108
    self.assertFalse(target.eh_utilizador(("name", "pass", "rule")))
AttributeError: module 'target' has no attribute 'eh_utilizador'

======================================================================
ERROR: test_eh_utilizador_109 (__main__.TestDepuracao5)
Exemplo enunciado {'name':'bruce','surname':'wayne','pass':'mynameisbatman','rule':{'vals':(2,8),'char':'m'}}
----------------------------------------------------------------------
Traceback (most recent call last):
  File "proj_tester.py", line 627, in test_eh_utilizador_109
    target.eh_utilizador(
AttributeError: module 'target' has no attribute 'eh_utilizador'

======================================================================
ERROR: test_eh_utilizador_110 (__main__.TestDepuracao5)
Exemplo enunciado {'pass':'mynameisbatman','rule':{'vals':(2,8),'char':'m'}}
----------------------------------------------------------------------
Traceback (most recent call last):
  File "proj_tester.py", line 642, in test_eh_utilizador_110
    target.eh_utilizador(
AttributeError: module 'target' has no attribute 'eh_utilizador'

======================================================================
ERROR: test_eh_utilizador_111 (__main__.TestDepuracao5)
Exemplo enunciado {'name':'','pass':'mynameisbatman','rule':{'vals':(2,8),'char':'m'}}
----------------------------------------------------------------------
Traceback (most recent call last):
  File "proj_tester.py", line 652, in test_eh_utilizador_111
    target.eh_utilizador(
AttributeError: module 'target' has no attribute 'eh_utilizador'

======================================================================
ERROR: test_eh_utilizador_112 (__main__.TestDepuracao5)
Exemplo enunciado {'name':'bruce.wayne','pass':'mynameisbatman','rule':{}}
----------------------------------------------------------------------
Traceback (most recent call last):
  File "proj_tester.py", line 666, in test_eh_utilizador_112
    target.eh_utilizador(
AttributeError: module 'target' has no attribute 'eh_utilizador'

======================================================================
ERROR: test_eh_utilizador_113 (__main__.TestDepuracao5)
----------------------------------------------------------------------
Traceback (most recent call last):
  File "proj_tester.py", line 673, in test_eh_utilizador_113
    target.eh_utilizador(
AttributeError: module 'target' has no attribute 'eh_utilizador'

======================================================================
ERROR: test_eh_utilizador_114 (__main__.TestDepuracao5)
----------------------------------------------------------------------
Traceback (most recent call last):
  File "proj_tester.py", line 684, in test_eh_utilizador_114
    target.eh_utilizador(
AttributeError: module 'target' has no attribute 'eh_utilizador'

======================================================================
ERROR: test_eh_utilizador_115 (__main__.TestDepuracao5)
----------------------------------------------------------------------
Traceback (most recent call last):
  File "proj_tester.py", line 695, in test_eh_utilizador_115
    target.eh_utilizador(
AttributeError: module 'target' has no attribute 'eh_utilizador'

======================================================================
ERROR: test_eh_utilizador_116 (__main__.TestDepuracao5)
----------------------------------------------------------------------
Traceback (most recent call last):
  File "proj_tester.py", line 706, in test_eh_utilizador_116
    target.eh_utilizador(
AttributeError: module 'target' has no attribute 'eh_utilizador'

======================================================================
ERROR: test_eh_utilizador_117 (__main__.TestDepuracao5)
Exemplo enunciado {'name':'bruce.wayne','pass':'mynameisbatman','rule':{'vals':(2,8),'char':'ma'}}
----------------------------------------------------------------------
Traceback (most recent call last):
  File "proj_tester.py", line 720, in test_eh_utilizador_117
    target.eh_utilizador(
AttributeError: module 'target' has no attribute 'eh_utilizador'

======================================================================
ERROR: test_eh_utilizador_118 (__main__.TestDepuracao5)
Exemplo enunciado {'name':'bruce.wayne','pass':'mynameisbatman','rule':{'vals':(2,8),'char':'m'}}
----------------------------------------------------------------------
Traceback (most recent call last):
  File "proj_tester.py", line 734, in test_eh_utilizador_118
    target.eh_utilizador(
AttributeError: module 'target' has no attribute 'eh_utilizador'

======================================================================
ERROR: test_filtrar_senhas_027 (__main__.TestDepuracao5)
----------------------------------------------------------------------
Traceback (most recent call last):
  File "proj_tester.py", line 811, in test_filtrar_senhas_027
    target.filtrar_senhas([])
AttributeError: module 'target' has no attribute 'filtrar_senhas'

======================================================================
ERROR: test_filtrar_senhas_028 (__main__.TestDepuracao5)
----------------------------------------------------------------------
Traceback (most recent call last):
  File "proj_tester.py", line 835, in test_filtrar_senhas_028
    target.filtrar_senhas(bdb),
AttributeError: module 'target' has no attribute 'filtrar_senhas'

======================================================================
ERROR: test_filtrar_senhas_129 (__main__.TestDepuracao5)
----------------------------------------------------------------------
Traceback (most recent call last):
  File "proj_tester.py", line 840, in test_filtrar_senhas_129
    target.filtrar_senhas(True)
AttributeError: module 'target' has no attribute 'filtrar_senhas'

======================================================================
ERROR: test_filtrar_senhas_130 (__main__.TestDepuracao5)
----------------------------------------------------------------------
Traceback (most recent call last):
  File "proj_tester.py", line 845, in test_filtrar_senhas_130
    target.filtrar_senhas("nothing")
AttributeError: module 'target' has no attribute 'filtrar_senhas'

======================================================================
ERROR: test_filtrar_senhas_131 (__main__.TestDepuracao5)
----------------------------------------------------------------------
Traceback (most recent call last):
  File "proj_tester.py", line 869, in test_filtrar_senhas_131
    target.filtrar_senhas(bdb),
AttributeError: module 'target' has no attribute 'filtrar_senhas'

======================================================================
ERROR: test_filtrar_senhas_132 (__main__.TestDepuracao5)
----------------------------------------------------------------------
Traceback (most recent call last):
  File "proj_tester.py", line 893, in test_filtrar_senhas_132
    target.filtrar_senhas(bdb),
AttributeError: module 'target' has no attribute 'filtrar_senhas'

======================================================================
ERROR: test_corrigir_doc_037 (__main__.TestDocumentacao1)
----------------------------------------------------------------------
Traceback (most recent call last):
  File "proj_tester.py", line 90, in test_corrigir_doc_037
    target.corrigir_doc(5)
  File "<string>", line 38, in corrigir_doc
AttributeError: 'int' object has no attribute 'split'

======================================================================
ERROR: test_corrigir_doc_038 (__main__.TestDocumentacao1)
----------------------------------------------------------------------
Traceback (most recent call last):
  File "proj_tester.py", line 95, in test_corrigir_doc_038
    target.corrigir_doc(())
  File "<string>", line 38, in corrigir_doc
AttributeError: 'tuple' object has no attribute 'split'

======================================================================
ERROR: test_corrigir_doc_039 (__main__.TestDocumentacao1)
----------------------------------------------------------------------
Traceback (most recent call last):
  File "proj_tester.py", line 100, in test_corrigir_doc_039
    target.corrigir_doc(["a", "b", "c"])
  File "<string>", line 38, in corrigir_doc
AttributeError: 'list' object has no attribute 'split'

======================================================================
ERROR: test_corrigir_doc_040 (__main__.TestDocumentacao1)
----------------------------------------------------------------------
Traceback (most recent call last):
  File "proj_tester.py", line 105, in test_corrigir_doc_040
    target.corrigir_doc(1234567)
  File "<string>", line 38, in corrigir_doc
AttributeError: 'int' object has no attribute 'split'

======================================================================
ERROR: test_corrigir_doc_043 (__main__.TestDocumentacao1)
----------------------------------------------------------------------
Traceback (most recent call last):
  File "proj_tester.py", line 119, in test_corrigir_doc_043
    self.assertEqual("Fundamentos da Programacao e Programacao com objetos", target.corrigir_doc(doc))
  File "<string>", line 48, in corrigir_doc
  File "<string>", line 18, in corrigir_palavra
UnboundLocalError: local variable 'pal_f' referenced before assignment

======================================================================
ERROR: test_corrigir_doc_044 (__main__.TestDocumentacao1)
----------------------------------------------------------------------
Traceback (most recent call last):
  File "proj_tester.py", line 123, in test_corrigir_doc_044
    self.assertEqual("Fundamentos da Programacao e programacao com objetos", target.corrigir_doc(doc))
  File "<string>", line 48, in corrigir_doc
  File "<string>", line 18, in corrigir_palavra
UnboundLocalError: local variable 'pal_f' referenced before assignment

======================================================================
ERROR: test_corrigir_doc_045 (__main__.TestDocumentacao1)
----------------------------------------------------------------------
Traceback (most recent call last):
  File "proj_tester.py", line 127, in test_corrigir_doc_045
    self.assertEqual("Programacao com objetos e", target.corrigir_doc(doc))
  File "<string>", line 48, in corrigir_doc
  File "<string>", line 18, in corrigir_palavra
UnboundLocalError: local variable 'pal_f' referenced before assignment

======================================================================
ERROR: test_filtrar_bdb_016 (__main__.TestVerificacaoDados3)
----------------------------------------------------------------------
Traceback (most recent call last):
  File "proj_tester.py", line 410, in test_filtrar_bdb_016
    target.filtrar_bdb(" ")
  File "<string>", line 209, in filtrar_bdb
IndexError: string index out of range

======================================================================
ERROR: test_filtrar_bdb_090 (__main__.TestVerificacaoDados3)
----------------------------------------------------------------------
Traceback (most recent call last):
  File "proj_tester.py", line 429, in test_filtrar_bdb_090
    target.filtrar_bdb(True)
  File "<string>", line 208, in filtrar_bdb
TypeError: object of type 'bool' has no len()

======================================================================
ERROR: test_filtrar_bdb_091 (__main__.TestVerificacaoDados3)
----------------------------------------------------------------------
Traceback (most recent call last):
  File "proj_tester.py", line 434, in test_filtrar_bdb_091
    target.filtrar_bdb([100])
  File "<string>", line 209, in filtrar_bdb
TypeError: 'int' object is not subscriptable

======================================================================
ERROR: test_filtrar_bdb_092 (__main__.TestVerificacaoDados3)
----------------------------------------------------------------------
Traceback (most recent call last):
  File "proj_tester.py", line 439, in test_filtrar_bdb_092
    target.filtrar_bdb([(), ()])
  File "<string>", line 209, in filtrar_bdb
IndexError: tuple index out of range

----------------------------------------------------------------------
Ran 159 tests in 0.043s

FAILED (errors=43)
